Workbook

Sheet Suppliers
A1: pdg_legacyid | B1: name | C1: pdg_categorycode | D1: pdg_categoryname | E1: pdg_zonecode | F1: pdg_zonename | G1: address1_line1 | H1: address1_line2 | I1: telephone1 | J1: telephone2 | K1: fax | L1: pdg_creditdays | M1: contact_name | N1: statecode | O1: statuscode
A2: 1 | B2: MDI | C2: F.S | D2: Foreign Supplier | E2: 0201 | F2: =_xlfn.XLOOKUP(Table3[[#This Row],[pdg_zonecode]],Zones!A:A,Zones!B:B) -> FRIBOURG | G2: FRIBOURG | L2: 0 | N2: 0 | O2: 1
A3: 10 | B3: PRIVATE LABEL DEVELOPMENT PLD | C3: F.S | D3: Foreign Supplier | E3: 0202 | F3: =_xlfn.XLOOKUP(Table3[[#This Row],[pdg_zonecode]],Zones!A:A,Zones!B:B) -> GENEVE | G3: CHEMIN FANTAISIE 2 CH 2300 LES CHAUX DES | H3: FONDS | I3: 039223159 | K3: 039223160 | L3: 0 | N3: 0 | O3: 1
A4: 100 | B4: DIMA ISSA | C4: L.S | D4: Local Supplier | E4: 01 | F4: =_xlfn.XLOOKUP(Table3[[#This Row],[pdg_zonecode]],Zones!A:A,Zones!B:B) -> LEBANON | I4: 03555663 | L4: 0 | N4: 0 | O4: 1
A5: 101 | B5: LINA AL-ASSAAD | C5: L.S | D5: Local Supplier | E5: 01 | F5: =_xlfn.XLOOKUP(Table3[[#This Row],[pdg_zonecode]],Zones!A:A,Zones!B:B) -> LEBANON | L5: 0 | N5: 0 | O5: 1
A6: 102 | B6: GHIDA HARIRI | C6: L.S | D6: Local Supplier | E6: 01 | F6: =_xlfn.XLOOKUP(Table3[[#This Row],[pdg_zonecode]],Zones!A:A,Zones!B:B) -> LEBANON | I6: 03318889 | L6: 0 | N6: 0 | O6: 1
A7: 103 | B7: MIRNA KASSIR | C7: L.S | D7: Local Supplier | E7: 0101 | F7: =_xlfn.XLOOKUP(Table3[[#This Row],[pdg_zonecode]],Zones!A:A,Zones!B:B) -> BEYROUTH | I7: 03146289 | L7: 0 | N7: 0 | O7: 1
A8: 104 | B8: JANINE FREIHA | C8: L.S | D8: Local Supplier | E8: 01 | F8: =_xlfn.XLOOKUP(Table3[[#This Row],[pdg_zonecode]],Zones!A:A,Zones!B:B) -> LEBANON | L8: 0 | N8: 0 | O8: 1
A9: 105 | B9: SUHA GAITH | C9: L.S | D9: Local Supplier | E9: 01 | F9: =_xlfn.XLOOKUP(Table3[[#This Row],[pdg_zonecode]],Zones!A:A,Zones!B:B) -> LEBANON | L9: 0 | N9: 0 | O9: 1
A10: 106 | B10: RANDA SAYYUR | C10: L.S | D10: Local Supplier | E10: 01 | F10: =_xlfn.XLOOKUP(Table3[[#This Row],[pdg_zonecode]],Zones!A:A,Zones!B:B) -> LEBANON | L10: 0 | N10: 0 | O10: 1
A11: 107 | B11: MICHELLE MALLAT RICHANI | C11: L.S | D11: Local Supplier | E11: 01 | F11: =_xlfn.XLOOKUP(Table3[[#This Row],[pdg_zonecode]],Zones!A:A,Zones!B:B) -> LEBANON | L11: 0 | N11: 0 | O11: 1
A12: 108 | B12: WORLD TRADING GEMS. | C12: L.S | D12: Local Supplier | E12: 01 | F12: =_xlfn.XLOOKUP(Table3[[#This Row],[pdg_zonecode]],Zones!A:A,Zones!B:B) -> LEBANON | L12: 0 | N12: 0 | O12: 1
A13: 109 | B13: RIM YEREVANIAN | C13: L.S | D13: Local Supplier | E13: 01 | F13: =_xlfn.XLOOKUP(Table3[[#This Row],[pdg_zonecode]],Zones!A:A,Zones!B:B) -> LEBANON | L13: 0 | N13: 0 | O13: 1
A14: 11 | B14: MECATTAF | C14: L.S | D14: Local Supplier | E14: 01 | F14: =_xlfn.XLOOKUP(Table3[[#This Row],[pdg_zonecode]],Zones!A:A,Zones!B:B) -> LEBANON | G14: DEBAYEH | L14: 0 | M14: MR. RAMEZ | N14: 0 | O14: 1
A15: 110 | B15: TAKAY JEWELLERY | C15: L.S | D15: Local Supplier | E15: 01 | F15: =_xlfn.XLOOKUP(Table3[[#This Row],[pdg_zonecode]],Zones!A:A,Zones!B:B) -> LEBANON | L15: 0 | N15: 0 | O15: 1
A16: 111 | B16: NABILA RASAMNY | C16: L.S | D16: Local Supplier | E16: 01 | F16: =_xlfn.XLOOKUP(Table3[[#This Row],[pdg_zonecode]],Zones!A:A,Zones!B:B) -> LEBANON | L16: 0 | N16: 0 | O16: 1
A17: 112 | B17: DAVCO | C17: L.S | D17: Local Supplier | E17: 0101 | F17: =_xlfn.XLOOKUP(Table3[[#This Row],[pdg_zonecode]],Zones!A:A,Zones!B:B) -> BEYROUTH | I17: 01881881 | K17: 9611881881 | L17: 0 | N17: 0 | O17: 1
A18: 113 | B18: LINA TANNIR | C18: L.S | D18: Local Supplier | E18: 0101 | F18: =_xlfn.XLOOKUP(Table3[[#This Row],[pdg_zonecode]],Zones!A:A,Zones!B:B) -> BEYROUTH | I18: 03773023 | L18: 0 | N18: 0 | O18: 1
A19: 114 | B19: FADY EID | C19: L.S | D19: Local Supplier | E19: 01 | F19: =_xlfn.XLOOKUP(Table3[[#This Row],[pdg_zonecode]],Zones!A:A,Zones!B:B) -> LEBANON | L19: 0 | N19: 0 | O19: 1
A20: 115 | B20: NISRINE NASR | C20: L.S | D20: Local Supplier | E20: 0101 | F20: =_xlfn.XLOOKUP(Table3[[#This Row],[pdg_zonecode]],Zones!A:A,Zones!B:B) -> BEYROUTH | I20: 03440404 | L20: 0 | N20: 0 | O20: 1
A21: 116 | B21: HAYSAM CHAHABY | C21: L.S | D21: Local Supplier | E21: 0101 | F21: =_xlfn.XLOOKUP(Table3[[#This Row],[pdg_zonecode]],Zones!A:A,Zones!B:B) -> BEYROUTH | I21: 03893535 | L21: 0 | N21: 0 | O21: 1
A22: 117 | B22: GEORGES KASSIS | C22: L.S | D22: Local Supplier | E22: 0101 | F22: =_xlfn.XLOOKUP(Table3[[#This Row],[pdg_zonecode]],Zones!A:A,Zones!B:B) -> BEYROUTH | I22: 03771067 | L22: 0 | N22: 0 | O22: 1
A23: 118 | B23: JOYCE MOKBEL | C23: L.S | D23: Local Supplier | E23: 0101 | F23: =_xlfn.XLOOKUP(Table3[[#This Row],[pdg_zonecode]],Zones!A:A,Zones!B:B) -> BEYROUTH | L23: 0 | N23: 0 | O23: 1
A24: 119 | B24: MAJD SLEIMAN | C24: L.S | D24: Local Supplier | E24: 0101 | F24: =_xlfn.XLOOKUP(Table3[[#This Row],[pdg_zonecode]],Zones!A:A,Zones!B:B) -> BEYROUTH | L24: 0 | N24: 0 | O24: 1
A25: 12 | B25: CLAL | C25: F.S | D25: Foreign Supplier | E25: 02 | F25: =_xlfn.XLOOKUP(Table3[[#This Row],[pdg_zonecode]],Zones!A:A,Zones!B:B) -> SWITZERLAND | L25: 0 | N25: 0 | O25: 1
A26: 120 | B26: MAHA ESTEPHAN | C26: L.S | D26: Local Supplier | E26: 0101 | F26: =_xlfn.XLOOKUP(Table3[[#This Row],[pdg_zonecode]],Zones!A:A,Zones!B:B) -> BEYROUTH | I26: 03237171 | L26: 0 | N26: 0 | O26: 1
A27: 121 | B27: RANA BAHRI | C27: L.S | D27: Local Supplier | E27: 0101 | F27: =_xlfn.XLOOKUP(Table3[[#This Row],[pdg_zonecode]],Zones!A:A,Zones!B:B) -> BEYROUTH | L27: 0 | N27: 0 | O27: 1
A28: 122 | B28: LINA CHOUEIRI | C28: L.S | D28: Local Supplier | E28: 0101 | F28: =_xlfn.XLOOKUP(Table3[[#This Row],[pdg_zonecode]],Zones!A:A,Zones!B:B) -> BEYROUTH | L28: 0 | N28: 0 | O28: 1
A29: 123 | B29: RANDA BENLADEN | C29: L.S | D29: Local Supplier | E29: 0101 | F29: =_xlfn.XLOOKUP(Table3[[#This Row],[pdg_zonecode]],Zones!A:A,Zones!B:B) -> BEYROUTH | L29: 0 | N29: 0 | O29: 1
A30: 124 | B30: GRACE KHAULI | C30: L.S | D30: Local Supplier | E30: 0101 | F30: =_xlfn.XLOOKUP(Table3[[#This Row],[pdg_zonecode]],Zones!A:A,Zones!B:B) -> BEYROUTH | L30: 0 | N30: 0 | O30: 1
A31: 125 | B31: MIREILLE EID | C31: L.S | D31: Local Supplier | E31: 0101 | F31: =_xlfn.XLOOKUP(Table3[[#This Row],[pdg_zonecode]],Zones!A:A,Zones!B:B) -> BEYROUTH | L31: 0 | N31: 0 | O31: 1
A32: 126 | B32: FARIDA EL ACHKAR | C32: L.S | D32: Local Supplier | E32: 0101 | F32: =_xlfn.XLOOKUP(Table3[[#This Row],[pdg_zonecode]],Zones!A:A,Zones!B:B) -> BEYROUTH | L32: 0 | N32: 0 | O32: 1
A33: 127 | B33: SALMA FAWAZ | C33: MISC | D33: Miscellaneous | E33: 0101 | F33: =_xlfn.XLOOKUP(Table3[[#This Row],[pdg_zonecode]],Zones!A:A,Zones!B:B) -> BEYROUTH | I33: 03728494 | L33: 0 | N33: 0 | O33: 1
A34: 128 | B34: MONA PAHARAON | C34: L.S | D34: Local Supplier | E34: 0101 | F34: =_xlfn.XLOOKUP(Table3[[#This Row],[pdg_zonecode]],Zones!A:A,Zones!B:B) -> BEYROUTH | I34: 03381260 | L34: 0 | N34: 0 | O34: 1
A35: 129 | B35: MONA HRAOUI | C35: L.S | D35: Local Supplier | E35: 0101 | F35: =_xlfn.XLOOKUP(Table3[[#This Row],[pdg_zonecode]],Zones!A:A,Zones!B:B) -> BEYROUTH | L35: 0 | N35: 0 | O35: 1
A36: 13 | B36: GUSTAV CEASER | C36: F.S | D36: Foreign Supplier | E36: 05 | F36: =_xlfn.XLOOKUP(Table3[[#This Row],[pdg_zonecode]],Zones!A:A,Zones!B:B) -> GERMANY | L36: 0 | N36: 0 | O36: 1
A37: 130 | B37: KRIKOR ISTANBOULIAN | C37: L.S | D37: Local Supplier | E37: 0101 | F37: =_xlfn.XLOOKUP(Table3[[#This Row],[pdg_zonecode]],Zones!A:A,Zones!B:B) -> BEYROUTH | G37: BOURJ HAMMOUD/MUNICIPALITY SQUARE | H37: MEKHITARIAN BLDG. | I37: 01243088 | J37: 03666185 | K37: 01243088 | L37: 0 | N37: 0 | O37: 1
A38: 131 | B38: RICH-ART MOUNTING HOUSE S.A.R. | C38: L.S | D38: Local Supplier | E38: 0101 | F38: =_xlfn.XLOOKUP(Table3[[#This Row],[pdg_zonecode]],Zones!A:A,Zones!B:B) -> BEYROUTH | I38: 01247242 | K38: 01266626 | L38: 0 | N38: 0 | O38: 1
A39: 132 | B39: RITA HILAL | C39: L.S | D39: Local Supplier | E39: 0101 | F39: =_xlfn.XLOOKUP(Table3[[#This Row],[pdg_zonecode]],Zones!A:A,Zones!B:B) -> BEYROUTH | L39: 0 | N39: 0 | O39: 1
A40: 133 | B40: HAYOULA YASSINE | C40: L.S | D40: Local Supplier | E40: 0101 | F40: =_xlfn.XLOOKUP(Table3[[#This Row],[pdg_zonecode]],Zones!A:A,Zones!B:B) -> BEYROUTH | I40: 03626394 | L40: 0 | N40: 0 | O40: 1
...

Sheet Zones
A1: code | B1: name | C1: Level | D1: ParentCode | E1: ParentName
A2: 26 | B2: ABU DHABI | C2: Country
A3: 2002 | B3: AL CHARKA | C3: City | D3: 20 | E3: EMIRATES
A4: 32 | B4: ALGERIA | C4: Country
A5: 1801 | B5: AMMAN | C5: City | D5: 18 | E5: JORDAN
A6: 2901 | B6: AMSTERDAM | C6: City | D6: 29 | E6: HOLLAND
A7: 25 | B7: AUSTRALIA | C7: Country
A8: 4101 | B8: BAGHDAD | C8: City | D8: 41 | E8: IRAQ
A9: 37 | B9: BAHRAIN | C9: Country
A10: 0901 | B10: BANGKOK | C10: City | D10: 09 | E10: THAILAND
A11: 090101 | B11: BANGRAK | C11: District | D11: 0901 | E11: BANGKOK
A12: 06 | B12: BELGIUM | C12: Country
A13: 0101 | B13: BEYROUTH | C13: City | D13: 01 | E13: LEBANON
A14: 38 | B14: BRAZIL | C14: Country
A15: 45 | B15: BRITISH VIRGIN ISLAND | C15: Country
A16: 1901 | B16: CAIRO | C16: City | D16: 19 | E16: EGYPT
A17: 16 | B17: CANADA | C17: Country
A18: 0801 | B18: COLOMBO 2 | C18: City | D18: 08 | E18: SRI LANKA
A19: 50 | B19: CONGO | C19: Country
A20: 47 | B20: COTE D'IVORE | C20: Country
A21: 10 | B21: CYPRUS | C21: Country
A22: 1701 | B22: DAMAS | C22: City | D22: 17 | E22: SYRIA
A23: 080101 | B23: DAWSON STREET | C23: District | D23: 0801 | E23: COLOMBO 2
A24: 1501 | B24: DOHA | C24: City | D24: 15 | E24: QATAR
A25: 2001 | B25: DUBAI | C25: City | D25: 20 | E25: EMIRATES
A26: 19 | B26: EGYPT | C26: Country
A27: 20 | B27: EMIRATES | C27: Country
A28: 11 | B28: ENGLAND | C28: Country
A29: 03 | B29: FRANCE | C29: Country
A30: 0201 | B30: FRIBOURG | C30: City | D30: 02 | E30: SWITZERLAND
A31: 0202 | B31: GENEVE | C31: City | D31: 02 | E31: SWITZERLAND
A32: 05 | B32: GERMANY | C32: Country
A33: 30 | B33: GHANA | C33: Country
A34: 23 | B34: GREECE | C34: Country
A35: 29 | B35: HOLLAND | C35: Country
A36: 46 | B36: HONGKONG | C36: Country
A37: 48 | B37: INDIA | C37: Country
A38: 39 | B38: IRAN | C38: Country
A39: 41 | B39: IRAQ | C39: Country
A40: 21 | B40: ITALY | C40: Country
...

Sheet SuppliersCategory
A1: code | B1: desc | C1: cyea | D1: lyea | E1: lyea1 | F1: lyea2 | G1: lyea3 | H1: lyea4
A2: MISC | B2: MCAT | C2: 0 | D2: 0 | E2: 0 | F2: 0 | G2: 0 | H2: 0
A3: F.S | B3: FOREIGN SUPPLIR | C3: 0 | D3: 0 | E3: 0 | F3: 0 | G3: 0 | H3: 0
A4: L.S | B4: LOCAL SUPPLIER | C4: 0 | D4: 0 | E4: 0 | F4: 0 | G4: 0 | H4: 0
